<mujoco model="diff_drive">
    <worldbody>
        <light diffuse="0.5 0.5 0.5" pos="0 0 3" dir="0 0 -1"/>
        <geom type="plane" size="10 10 0.01" rgba="0.9 0.9 0.9 1" friction="1.0 0.005 0.0001"/>
        <body name="chassis" pos="0 0 0.2" euler="0 90 0">
            <joint type="free"/>
            <geom type="box" size="0.05 0.2 0.5" rgba="0.9 0.9 0 1"/>
            <body pos="0 0.3 -0.5" euler="90 0 0">
                <joint name="left-wheel" type="hinge" axis="0 0 -1"/>
                <geom type="cylinder" size="0.2 0.05" rgba="0 0.9 0 1" friction="0.8 0.005 0.0001"/>
            </body>
            <body pos="0 -0.3 -0.5" euler="90 0 0">
                <joint name="right-wheel" type="hinge" axis="0 0 -1"/>
                <geom type="cylinder" size="0.2 0.05" rgba="0 0.9 0 1" friction="0.8 0.005 0.0001"/>
            </body>
            <body pos="0 0 0.5" euler="90 0 0">
                <joint name="caster" type="ball"/>
                <geom type="sphere" size="0.15" rgba="0 0.9 0 1"/>
            </body>
        </body>
    </worldbody>

    <actuator>
        <velocity name="left-velocity-servo" joint="left-wheel" kv="100"/>
        <velocity name="right-velocity-servo" joint="right-wheel" kv="100"/>
    </actuator>
</mujoco>